Workbook
Name DCF: OFFSET('Adjust Cash Flow'!$B$18,0,0,COUNT('Adjust Cash Flow'!$B$17:$B$1483)+1,9)
Name WAllowance: '4) Happy Money'!$E$26

Sheet 1) Period
B6: Budget Spreadsheet
B7: Thank you for using our spreadsheet! Let's guide you through the steps to create your budget
D8: CLICK HERE for a video showing how to use the spreadsheet!
B10: 1) Period
C11: The first step is to figure out the period of time that your budget will cover.
D12: (When does your budget start and how far are we looking into the future?)
C13: You can start on any day of the week or month.
C14: The end should usually be a year or two into the future. (52 - 104 weeks)
D15: *The budget doesn't actually end on that date. The calculations need to know how far to look forward.
D16: *Just type in the start date and the number of weeks. The spreadhseet will do the rest.
D18: Start | E18: 45474 | K18: Currency
D19: Weeks | E19: 104 | K19: Dollar
D20: Years | E20: =(DATEDIF(E18,E21,"M")+1)/12 -> 2
D21: End | E21: =E18+(E19*7)-1 -> 46201
B23: --> Follow the tabs along the bottom for the next steps!
B25: Copyright 2022 The Happy Giraffe Company. All rights reserved.

Sheet 2) Income
B2: 2) Income
C3: Now let's figure out how much money you have to work with.
C4: Include the money in your bank account and any regular income.
C5: Don't include income you can't count on or savings you don't want to spend.
C6: *Savings accounts, tax returns, over-time hours, gifts, etc...
C7: Let these be good surprises to your budget.
C9: Bank Balance | D9: 1250
C11: Income Sources:
C12: Name | D12: Frequency | E12: Take Home Amount | F12: Next Pay Date | H12: Start Month | I12: Start Day
C13: My Main Paycheck | D13: Every Other Week | E13: 2300 | F13: 45478 | H13: =IF(F13="","",MONTH(F13)) -> 7 | I13: =IF(F13="","",DAY(F13)) -> 5
C14: My estimated side income | D14: Monthly | E14: 650 | F14: 45474 | H14: =IF(F14="","",MONTH(F14)) -> 7 | I14: =IF(F14="","",DAY(F14)) -> 1
H15: =IF(F15="","",MONTH(F15)) | I15: =IF(F15="","",DAY(F15))
H16: =IF(F16="","",MONTH(F16)) | I16: =IF(F16="","",DAY(F16))
H17: =IF(F17="","",MONTH(F17)) | I17: =IF(F17="","",DAY(F17))
H18: =IF(F18="","",MONTH(F18)) | I18: =IF(F18="","",DAY(F18))
H19: =IF(F19="","",MONTH(F19)) | I19: =IF(F19="","",DAY(F19))
H20: =IF(F20="","",MONTH(F20)) | I20: =IF(F20="","",DAY(F20))
H21: =IF(F21="","",MONTH(F21)) | I21: =IF(F21="","",DAY(F21))
H22: =IF(F22="","",MONTH(F22)) | I22: =IF(F22="","",DAY(F22))
H23: =IF(F23="","",MONTH(F23)) | I23: =IF(F23="","",DAY(F23))
H24: =IF(F24="","",MONTH(F24)) | I24: =IF(F24="","",DAY(F24))
H25: =IF(F25="","",MONTH(F25)) | I25: =IF(F25="","",DAY(F25))
H26: =IF(F26="","",MONTH(F26)) | I26: =IF(F26="","",DAY(F26))
... H32: =IF(F32="","",MONTH(F32)) | I32: =IF(F32="","",DAY(F32))

Sheet 3) Fixed Expenses
B2: 3) Fixed Expenses
C3: Next, list your fixed expenses.
C4: Fixed expenses occur on a regular basis and the amount usually stays the same.
C5: Include tithing, savings, and other fixed expenses in the sections below.
C6: Don't include expenses that change frequently like eating out or entertainment.
C9: Monthly | G9: Yearly | M9: One-Time | Q9: Other
C10: Monthly Total | D10: =SUM(TMonthly[Amount]) -> 3200 | G10: Yearly Total | H10: =SUM(TYearly[Amount]) -> 1400 | M10: One-Time Total | N10: =SUM(TOneTime[Amount]) -> 700 | R10: Other Total | S10: =SUM(TOther[Amount]) -> 705
C11: Description | D11: Amount | E11: Day of the Month | G11: Description | H11: Amount | I11: Due Date | J11: Month | K11: Day | M11: Description | N11: Amount | O11: Due Date | Q11: Description | R11: Amount | S11: Frequency | T11: Start Date | U11: End Date | V11: Start Month | W11: Start Day | X11: End Date Calc
C12: Mortgage/Rent | D12: 2000 | E12: 31 | G12: Car Registration | H12: 300 | I12: 45444 | J12: =IF(TYearly[[#This Row],[Due Date]]="","",MONTH(TYearly[[#This Row],[Due Date]])) -> 6 | K12: =IF(TYearly[[#This Row],[Due Date]]="","",DAY(TYearly[[#This Row],[Due Date]])) -> 1 | M12: Credit Card Payoff | N12: 500 | O12: 45482 | Q12: Charity | R12: 230 | S12: Every Other Week | T12: 45509 | V12: =IF(TOther[[#This Row],[Start Date]]="","",MONTH(TOther[[#This Row],[Start Date]])) -> 8 | W12: =IF(TOther[[#This Row],[Start Date]]="","",DAY(TOther[[#This Row],[Start Date]])) -> 5 | X12: =IF(TOther[[#This Row],[End Date]]="",DATE(3000,12,31),TOther[[#This Row],[End Date]]) -> 402133
C13: Utilities | D13: 300 | E13: 11 | G13: Subscription | H13: 100 | I13: 45597 | J13: =IF(TYearly[[#This Row],[Due Date]]="","",MONTH(TYearly[[#This Row],[Due Date]])) -> 11 | K13: =IF(TYearly[[#This Row],[Due Date]]="","",DAY(TYearly[[#This Row],[Due Date]])) -> 1 | M13: Birthday Party | N13: 200 | O13: 45505 | Q13: Subscription | R13: 75 | S13: Monthly | T13: 45529 | U13: 45590 | V13: =IF(TOther[[#This Row],[Start Date]]="","",MONTH(TOther[[#This Row],[Start Date]])) -> 8 | W13: =IF(TOther[[#This Row],[Start Date]]="","",DAY(TOther[[#This Row],[Start Date]])) -> 25 | X13: =IF(TOther[[#This Row],[End Date]]="",DATE(3000,12,31),TOther[[#This Row],[End Date]]) -> 45590
C14: Internet/Cable | D14: 100 | E14: 10 | G14: Christmas | H14: 1000 | I14: 45627 | J14: =IF(TYearly[[#This Row],[Due Date]]="","",MONTH(TYearly[[#This Row],[Due Date]])) -> 12 | K14: =IF(TYearly[[#This Row],[Due Date]]="","",DAY(TYearly[[#This Row],[Due Date]])) -> 1 | Q14: Car Insurance | R14: 400 | S14: Every 6 Months | T14: 45458 | V14: =IF(TOther[[#This Row],[Start Date]]="","",MONTH(TOther[[#This Row],[Start Date]])) -> 6 | W14: =IF(TOther[[#This Row],[Start Date]]="","",DAY(TOther[[#This Row],[Start Date]])) -> 15 | X14: =IF(TOther[[#This Row],[End Date]]="",DATE(3000,12,31),TOther[[#This Row],[End Date]]) -> 402133
C15: Car Payment | D15: 400 | E15: 10 | J15: =IF(TYearly[[#This Row],[Due Date]]="","",MONTH(TYearly[[#This Row],[Due Date]])) | K15: =IF(TYearly[[#This Row],[Due Date]]="","",DAY(TYearly[[#This Row],[Due Date]])) | V15: =IF(TOther[[#This Row],[Start Date]]="","",MONTH(TOther[[#This Row],[Start Date]])) | W15: =IF(TOther[[#This Row],[Start Date]]="","",DAY(TOther[[#This Row],[Start Date]])) | X15: =IF(TOther[[#This Row],[End Date]]="",DATE(3000,12,31),TOther[[#This Row],[End Date]]) -> 402133
C16: Cell Phone | D16: 100 | E16: 27 | J16: =IF(TYearly[[#This Row],[Due Date]]="","",MONTH(TYearly[[#This Row],[Due Date]])) | K16: =IF(TYearly[[#This Row],[Due Date]]="","",DAY(TYearly[[#This Row],[Due Date]])) | V16: =IF(TOther[[#This Row],[Start Date]]="","",MONTH(TOther[[#This Row],[Start Date]])) | W16: =IF(TOther[[#This Row],[Start Date]]="","",DAY(TOther[[#This Row],[Start Date]])) | X16: =IF(TOther[[#This Row],[End Date]]="",DATE(3000,12,31),TOther[[#This Row],[End Date]]) -> 402133
C17: Subscription | D17: 50 | E17: 1 | J17: =IF(TYearly[[#This Row],[Due Date]]="","",MONTH(TYearly[[#This Row],[Due Date]])) | K17: =IF(TYearly[[#This Row],[Due Date]]="","",DAY(TYearly[[#This Row],[Due Date]])) | V17: =IF(TOther[[#This Row],[Start Date]]="","",MONTH(TOther[[#This Row],[Start Date]])) | W17: =IF(TOther[[#This Row],[Start Date]]="","",DAY(TOther[[#This Row],[Start Date]])) | X17: =IF(TOther[[#This Row],[End Date]]="",DATE(3000,12,31),TOther[[#This Row],[End Date]]) -> 402133
C18: Savings | D18: 50 | E18: 1 | J18: =IF(TYearly[[#This Row],[Due Date]]="","",MONTH(TYearly[[#This Row],[Due Date]])) | K18: =IF(TYearly[[#This Row],[Due Date]]="","",DAY(TYearly[[#This Row],[Due Date]])) | V18: =IF(TOther[[#This Row],[Start Date]]="","",MONTH(TOther[[#This Row],[Start Date]])) | W18: =IF(TOther[[#This Row],[Start Date]]="","",DAY(TOther[[#This Row],[Start Date]])) | X18: =IF(TOther[[#This Row],[End Date]]="",DATE(3000,12,31),TOther[[#This Row],[End Date]]) -> 402133
C19: Debt 1 | D19: 95 | E19: 1 | J19: =IF(TYearly[[#This Row],[Due Date]]="","",MONTH(TYearly[[#This Row],[Due Date]])) | K19: =IF(TYearly[[#This Row],[Due Date]]="","",DAY(TYearly[[#This Row],[Due Date]])) | V19: =IF(TOther[[#This Row],[Start Date]]="","",MONTH(TOther[[#This Row],[Start Date]])) | W19: =IF(TOther[[#This Row],[Start Date]]="","",DAY(TOther[[#This Row],[Start Date]])) | X19: =IF(TOther[[#This Row],[End Date]]="",DATE(3000,12,31),TOther[[#This Row],[End Date]]) -> 402133
C20: Debt 2 | D20: 35 | E20: 2 | J20: =IF(TYearly[[#This Row],[Due Date]]="","",MONTH(TYearly[[#This Row],[Due Date]])) | K20: =IF(TYearly[[#This Row],[Due Date]]="","",DAY(TYearly[[#This Row],[Due Date]])) | V20: =IF(TOther[[#This Row],[Start Date]]="","",MONTH(TOther[[#This Row],[Start Date]])) | W20: =IF(TOther[[#This Row],[Start Date]]="","",DAY(TOther[[#This Row],[Start Date]])) | X20: =IF(TOther[[#This Row],[End Date]]="",DATE(3000,12,31),TOther[[#This Row],[End Date]]) -> 402133
C21: Debt 3 | D21: 35 | E21: 3 | J21: =IF(TYearly[[#This Row],[Due Date]]="","",MONTH(TYearly[[#This Row],[Due Date]])) | K21: =IF(TYearly[[#This Row],[Due Date]]="","",DAY(TYearly[[#This Row],[Due Date]])) | V21: =IF(TOther[[#This Row],[Start Date]]="","",MONTH(TOther[[#This Row],[Start Date]])) | W21: =IF(TOther[[#This Row],[Start Date]]="","",DAY(TOther[[#This Row],[Start Date]])) | X21: =IF(TOther[[#This Row],[End Date]]="",DATE(3000,12,31),TOther[[#This Row],[End Date]]) -> 402133
C22: Debt 4 | D22: 35 | E22: 4 | J22: =IF(TYearly[[#This Row],[Due Date]]="","",MONTH(TYearly[[#This Row],[Due Date]])) | K22: =IF(TYearly[[#This Row],[Due Date]]="","",DAY(TYearly[[#This Row],[Due Date]])) | V22: =IF(TOther[[#This Row],[Start Date]]="","",MONTH(TOther[[#This Row],[Start Date]])) | W22: =IF(TOther[[#This Row],[Start Date]]="","",DAY(TOther[[#This Row],[Start Date]])) | X22: =IF(TOther[[#This Row],[End Date]]="",DATE(3000,12,31),TOther[[#This Row],[End Date]]) -> 402133
J23: =IF(TYearly[[#This Row],[Due Date]]="","",MONTH(TYearly[[#This Row],[Due Date]])) | K23: =IF(TYearly[[#This Row],[Due Date]]="","",DAY(TYearly[[#This Row],[Due Date]])) | V23: =IF(TOther[[#This Row],[Start Date]]="","",MONTH(TOther[[#This Row],[Start Date]])) | W23: =IF(TOther[[#This Row],[Start Date]]="","",DAY(TOther[[#This Row],[Start Date]])) | X23: =IF(TOther[[#This Row],[End Date]]="",DATE(3000,12,31),TOther[[#This Row],[End Date]]) -> 402133
J24: =IF(TYearly[[#This Row],[Due Date]]="","",MONTH(TYearly[[#This Row],[Due Date]])) | K24: =IF(TYearly[[#This Row],[Due Date]]="","",DAY(TYearly[[#This Row],[Due Date]])) | V24: =IF(TOther[[#This Row],[Start Date]]="","",MONTH(TOther[[#This Row],[Start Date]])) | W24: =IF(TOther[[#This Row],[Start Date]]="","",DAY(TOther[[#This Row],[Start Date]])) | X24: =IF(TOther[[#This Row],[End Date]]="",DATE(3000,12,31),TOther[[#This Row],[End Date]]) -> 402133
J25: =IF(TYearly[[#This Row],[Due Date]]="","",MONTH(TYearly[[#This Row],[Due Date]])) | K25: =IF(TYearly[[#This Row],[Due Date]]="","",DAY(TYearly[[#This Row],[Due Date]])) | V25: =IF(TOther[[#This Row],[Start Date]]="","",MONTH(TOther[[#This Row],[Start Date]])) | W25: =IF(TOther[[#This Row],[Start Date]]="","",DAY(TOther[[#This Row],[Start Date]])) | X25: =IF(TOther[[#This Row],[End Date]]="",DATE(3000,12,31),TOther[[#This Row],[End Date]]) -> 402133
J26: =IF(TYearly[[#This Row],[Due Date]]="","",MONTH(TYearly[[#This Row],[Due Date]])) | K26: =IF(TYearly[[#This Row],[Due Date]]="","",DAY(TYearly[[#This Row],[Due Date]])) | V26: =IF(TOther[[#This Row],[Start Date]]="","",MONTH(TOther[[#This Row],[Start Date]])) | W26: =IF(TOther[[#This Row],[Start Date]]="","",DAY(TOther[[#This Row],[Start Date]])) | X26: =IF(TOther[[#This Row],[End Date]]="",DATE(3000,12,31),TOther[[#This Row],[End Date]]) -> 402133
J27: =IF(TYearly[[#This Row],[Due Date]]="","",MONTH(TYearly[[#This Row],[Due Date]])) | K27: =IF(TYearly[[#This Row],[Due Date]]="","",DAY(TYearly[[#This Row],[Due Date]])) | V27: =IF(TOther[[#This Row],[Start Date]]="","",MONTH(TOther[[#This Row],[Start Date]])) | W27: =IF(TOther[[#This Row],[Start Date]]="","",DAY(TOther[[#This Row],[Start Date]])) | X27: =IF(TOther[[#This Row],[End Date]]="",DATE(3000,12,31),TOther[[#This Row],[End Date]]) -> 402133
J28: =IF(TYearly[[#This Row],[Due Date]]="","",MONTH(TYearly[[#This Row],[Due Date]])) | K28: =IF(TYearly[[#This Row],[Due Date]]="","",DAY(TYearly[[#This Row],[Due Date]])) | V28: =IF(TOther[[#This Row],[Start Date]]="","",MONTH(TOther[[#This Row],[Start Date]])) | W28: =IF(TOther[[#This Row],[Start Date]]="","",DAY(TOther[[#This Row],[Start Date]])) | X28: =IF(TOther[[#This Row],[End Date]]="",DATE(3000,12,31),TOther[[#This Row],[End Date]]) -> 402133
J29: =IF(TYearly[[#This Row],[Due Date]]="","",MONTH(TYearly[[#This Row],[Due Date]])) | K29: =IF(TYearly[[#This Row],[Due Date]]="","",DAY(TYearly[[#This Row],[Due Date]])) | V29: =IF(TOther[[#This Row],[Start Date]]="","",MONTH(TOther[[#This Row],[Start Date]])) | W29: =IF(TOther[[#This Row],[Start Date]]="","",DAY(TOther[[#This Row],[Start Date]])) | X29: =IF(TOther[[#This Row],[End Date]]="",DATE(3000,12,31),TOther[[#This Row],[End Date]]) -> 402133
J30: =IF(TYearly[[#This Row],[Due Date]]="","",MONTH(TYearly[[#This Row],[Due Date]])) | K30: =IF(TYearly[[#This Row],[Due Date]]="","",DAY(TYearly[[#This Row],[Due Date]])) | V30: =IF(TOther[[#This Row],[Start Date]]="","",MONTH(TOther[[#This Row],[Start Date]])) | W30: =IF(TOther[[#This Row],[Start Date]]="","",DAY(TOther[[#This Row],[Start Date]])) | X30: =IF(TOther[[#This Row],[End Date]]="",DATE(3000,12,31),TOther[[#This Row],[End Date]]) -> 402133
J31: =IF(TYearly[[#This Row],[Due Date]]="","",MONTH(TYearly[[#This Row],[Due Date]])) | K31: =IF(TYearly[[#This Row],[Due Date]]="","",DAY(TYearly[[#This Row],[Due Date]])) | V31: =IF(TOther[[#This Row],[Start Date]]="","",MONTH(TOther[[#This Row],[Start Date]])) | W31: =IF(TOther[[#This Row],[Start Date]]="","",DAY(TOther[[#This Row],[Start Date]])) | X31: =IF(TOther[[#This Row],[End Date]]="",DATE(3000,12,31),TOther[[#This Row],[End Date]]) -> 402133
J32: =IF(TYearly[[#This Row],[Due Date]]="","",MONTH(TYearly[[#This Row],[Due Date]])) | K32: =IF(TYearly[[#This Row],[Due Date]]="","",DAY(TYearly[[#This Row],[Due Date]])) | V32: =IF(TOther[[#This Row],[Start Date]]="","",MONTH(TOther[[#This Row],[Start Date]])) | W32: =IF(TOther[[#This Row],[Start Date]]="","",DAY(TOther[[#This Row],[Start Date]])) | X32: =IF(TOther[[#This Row],[End Date]]="",DATE(3000,12,31),TOther[[#This Row],[End Date]]) -> 402133
J33: =IF(TYearly[[#This Row],[Due Date]]="","",MONTH(TYearly[[#This Row],[Due Date]])) | K33: =IF(TYearly[[#This Row],[Due Date]]="","",DAY(TYearly[[#This Row],[Due Date]])) | V33: =IF(TOther[[#This Row],[Start Date]]="","",MONTH(TOther[[#This Row],[Start Date]])) | W33: =IF(TOther[[#This Row],[Start Date]]="","",DAY(TOther[[#This Row],[Start Date]])) | X33: =IF(TOther[[#This Row],[End Date]]="",DATE(3000,12,31),TOther[[#This Row],[End Date]]) -> 402133
J34: =IF(TYearly[[#This Row],[Due Date]]="","",MONTH(TYearly[[#This Row],[Due Date]])) | K34: =IF(TYearly[[#This Row],[Due Date]]="","",DAY(TYearly[[#This Row],[Due Date]])) | V34: =IF(TOther[[#This Row],[Start Date]]="","",MONTH(TOther[[#This Row],[Start Date]])) | W34: =IF(TOther[[#This Row],[Start Date]]="","",DAY(TOther[[#This Row],[Start Date]])) | X34: =IF(TOther[[#This Row],[End Date]]="",DATE(3000,12,31),TOther[[#This Row],[End Date]]) -> 402133
... J131: =IF(TYearly[[#This Row],[Due Date]]="","",MONTH(TYearly[[#This Row],[Due Date]])) | K131: =IF(TYearly[[#This Row],[Due Date]]="","",DAY(TYearly[[#This Row],[Due Date]])) | V131: =IF(TOther[[#This Row],[Start Date]]="","",MONTH(TOther[[#This Row],[Start Date]])) | W131: =IF(TOther[[#This Row],[Start Date]]="","",DAY(TOther[[#This Row],[Start Date]])) | X131: =IF(TOther[[#This Row],[End Date]]="",DATE(3000,12,31),TOther[[#This Row],[End Date]]) -> 402133

Sheet 4) Happy Money
B2: 4) Happy Money = | E2: =WAllowance -> 400 | F2: Per Week
C4: Below is your maximum weekly allowance in an easy, perfect world.
C6: Total Income | D6: Minus | E6: Total Fixed Expenses | F6: Equals | G6: Spendable Money
C7: ='2) Income'!D9+SUM('Detailed Cash Flow'!AJ2:AJ1466) -> 136450 | D7: - | E7: =-SUM('Adjust Cash Flow'!C19:F1483,'Adjust Cash Flow'!I19:I1483) -> 91625 | F7: = | G7: =C7-E7 -> 44825
C9: Spendable Money | D9: Divided by | E9: Weeks | F9: Equals | G9: Max. Weekly Allowance
C10: =G7 -> 44825 | D10: / | E10: ='1) Period'!E19 -> 104 | F10: = | G10: =G7/'1) Period'!E19 -> 431.00962
B12: Why you need the spreadsheet!
C13: In reality, life isn't that simple. Most of us have to worry about something called CASH FLOW.
C14: Your max allowance assumes you have all of the cash available right when you need it (which doesn't always happen).
C15: It also assumes you want to be COMPLETELY BROKE at the end of your budget period (probably not the case).
B17: Make the CASH FLOW work
C18: 1) Choose your refill day (the day your allowance resets each week)
C19: 2) Pro-Rated shows a smaller amount to use until your first refill day.
C20: 3) Start with the Max amount, then adjust your Actual until all 3 checks stay green.
C21: ="*This is where the spreadsheet does the hard work for you. It is calculating your daily personal cash flow for the next " & '1) Period'!E19& " weeks!" -> *This is where the spreadsheet does the hard work for you. It is calculating your daily personal cash flow for the next 104 weeks!
C23: Select the day --> | D23: Refill Day | E23: Monday
D25: Max weekly | E25: =G10 -> 431.00962
C26: Adjust this one! --> | D26: Actual weekly | E26: 400 | H26: =VLOOKUP($E$23,Lists!$D$1:$E$7,2,FALSE) -> 2
H27: =WEEKDAY('1) Period'!E18,1) -> 2
D28: Pro-Rated | E28: ='Detailed Cash Flow'!D2 -> 400 | F28: =IF(E28=WAllowance,"Today is your refill day! You get the full amount!","This is your starting amount to use until your first refill day.") -> Today is your refill day! You get the full amount! | H28: =IF(H26>=H27,(H26-H27),7-(H27-H26)) -> 0
B30: How to Know It Works
C31: Use these 3 checks to make sure your allowance works in real life.
C32: *They use your cash flow chart (the next tab) to show what’s working and what’s not.
C34: Days your account will go negative: | E34: =COUNTIF('Adjust Cash Flow'!K19:K1483,"<0") -> 0
E35: You want this to be 0 (not a negative number!)
C37: Your lowest bank balance: | E37: =MIN('Adjust Cash Flow'!K19:K1483) -> 95 | F37: happens on | G37: =INDEX('Adjust Cash Flow'!B19:B1483, MATCH(MIN('Adjust Cash Flow'!K19:K1483), 'Adjust Cash Flow'!K19:K1483, 0)) -> 45657
E38: ="Keep this number above zero! It shows your lowest point over the next " & '1) Period'!E19& " weeks!" -> Keep this number above zero! It shows your lowest point over the next 104 weeks!
C40: You are over/under spending by: | E40: =SLOPE('Adjust Cash Flow'!$K19:$K1483,'Adjust Cash Flow'!$B19:$B1483)*7 -> 3.5307687 | F40: per week
C41: *Spreadsheet linear regression magic. | E41: Smaller is better. Just keep the other checks green!
E42: This number shows how much money is sitting unused each week.
E43: A small number means you're spending, saving, or planning for every dollar (which is the goal!)

Sheet Cash Flow Chart
H30: For details about each day go to the next tab on the bottom called "Adjust Cash Flow"

Sheet Adjust Cash Flow
B2: Adjust cash flow
B3: Here's a glimpse into some of the magic that the spreadsheet is doing for you.
B4: You can see day by day what is being projected for your fixed expenses, income, and weekly allowance.
B5: The first few days of your budget may need some adjustments. Use the Adjustment column for this.
B6: *Positive numbers add money (or undo an expense), negative numbers remove money.
B8: Example of removing an expense: A monthly fixed expense ($100) usually happens on the 10th, but you paid it early. If your budget starts on the 10th, the chart below will show ($100) in the month column. This needs to be corrected so you aren't "paying for it" twice. In the adjustment column enter $100 (as a positive number). The bank balance column will increase $100, correcting it for the month.
B12: Date | C12: Week | D12: Month | E12: Year | F12: One-time | G12: Income | H12: Allowance | I12: Adjustment | J12: Notes | K12: Bank Balance
B13: 43200 | C13: 0 | D13: -100 | E13: 0 | F13: 0 | G13: 0 | H13: 0 | I13: 100 | J13: Paid Early | K13: 1625
C17: Fixed Expenses
B18: Date | C18: Month | D18: Year | E18: One-time | F18: Other | G18: Income | H18: Allowance | I18: Adjustment | J18: Notes | K18: Bank Balance | L18: Chart
B19: ='Detailed Cash Flow'!A2 -> 45474 | C19: =IF('Detailed Cash Flow'!E2="","",'Detailed Cash Flow'!E2*-1) -> -195 | D19: =IF('Detailed Cash Flow'!F2="","",'Detailed Cash Flow'!F2*-1) -> 0 | E19: =IF('Detailed Cash Flow'!G2="","",'Detailed Cash Flow'!G2*-1) -> 0 | F19: =IF('Detailed Cash Flow'!Y2="","",'Detailed Cash Flow'!Y2*-1) -> 0 | G19: ='Detailed Cash Flow'!AJ2 -> 650 | H19: =IF('Detailed Cash Flow'!D2="","",'Detailed Cash Flow'!D2*-1) -> -400 | K19: =IF(B19="","",'2) Income'!$D$9+G19+C19+D19+E19+F19+H19+I19) -> 1305 | L19: =K19 -> 1305
B20: ='Detailed Cash Flow'!A3 -> 45475 | C20: =IF('Detailed Cash Flow'!E3="","",'Detailed Cash Flow'!E3*-1) -> -35 | D20: =IF('Detailed Cash Flow'!F3="","",'Detailed Cash Flow'!F3*-1) -> 0 | E20: =IF('Detailed Cash Flow'!G3="","",'Detailed Cash Flow'!G3*-1) -> 0 | F20: =IF('Detailed Cash Flow'!Y3="","",'Detailed Cash Flow'!Y3*-1) -> 0 | G20: ='Detailed Cash Flow'!AJ3 -> 0 | H20: =IF('Detailed Cash Flow'!D3="","",'Detailed Cash Flow'!D3*-1) -> 0 | K20: =IF(B20="","",K19+G20+C20+D20+E20+F20+H20+I20) -> 1270 | L20: =K20 -> 1270
B21: ='Detailed Cash Flow'!A4 -> 45476 | C21: =IF('Detailed Cash Flow'!E4="","",'Detailed Cash Flow'!E4*-1) -> -35 | D21: =IF('Detailed Cash Flow'!F4="","",'Detailed Cash Flow'!F4*-1) -> 0 | E21: =IF('Detailed Cash Flow'!G4="","",'Detailed Cash Flow'!G4*-1) -> 0 | F21: =IF('Detailed Cash Flow'!Y4="","",'Detailed Cash Flow'!Y4*-1) -> 0 | G21: ='Detailed Cash Flow'!AJ4 -> 0 | H21: =IF('Detailed Cash Flow'!D4="","",'Detailed Cash Flow'!D4*-1) -> 0 | K21: =IF(B21="","",K20+G21+C21+D21+E21+F21+H21+I21) -> 1235 | L21: =K21 -> 1235
B22: ='Detailed Cash Flow'!A5 -> 45477 | C22: =IF('Detailed Cash Flow'!E5="","",'Detailed Cash Flow'!E5*-1) -> -35 | D22: =IF('Detailed Cash Flow'!F5="","",'Detailed Cash Flow'!F5*-1) -> 0 | E22: =IF('Detailed Cash Flow'!G5="","",'Detailed Cash Flow'!G5*-1) -> 0 | F22: =IF('Detailed Cash Flow'!Y5="","",'Detailed Cash Flow'!Y5*-1) -> 0 | G22: ='Detailed Cash Flow'!AJ5 -> 0 | H22: =IF('Detailed Cash Flow'!D5="","",'Detailed Cash Flow'!D5*-1) -> 0 | K22: =IF(B22="","",K21+G22+C22+D22+E22+F22+H22+I22) -> 1200 | L22: =K22 -> 1200
B23: ='Detailed Cash Flow'!A6 -> 45478 | C23: =IF('Detailed Cash Flow'!E6="","",'Detailed Cash Flow'!E6*-1) -> 0 | D23: =IF('Detailed Cash Flow'!F6="","",'Detailed Cash Flow'!F6*-1) -> 0 | E23: =IF('Detailed Cash Flow'!G6="","",'Detailed Cash Flow'!G6*-1) -> 0 | F23: =IF('Detailed Cash Flow'!Y6="","",'Detailed Cash Flow'!Y6*-1) -> 0 | G23: ='Detailed Cash Flow'!AJ6 -> 2300 | H23: =IF('Detailed Cash Flow'!D6="","",'Detailed Cash Flow'!D6*-1) -> 0 | K23: =IF(B23="","",K22+G23+C23+D23+E23+F23+H23+I23) -> 3500 | L23: =K23 -> 3500
B24: ='Detailed Cash Flow'!A7 -> 45479 | C24: =IF('Detailed Cash Flow'!E7="","",'Detailed Cash Flow'!E7*-1) -> 0 | D24: =IF('Detailed Cash Flow'!F7="","",'Detailed Cash Flow'!F7*-1) -> 0 | E24: =IF('Detailed Cash Flow'!G7="","",'Detailed Cash Flow'!G7*-1) -> 0 | F24: =IF('Detailed Cash Flow'!Y7="","",'Detailed Cash Flow'!Y7*-1) -> 0 | G24: ='Detailed Cash Flow'!AJ7 -> 0 | H24: =IF('Detailed Cash Flow'!D7="","",'Detailed Cash Flow'!D7*-1) -> 0 | K24: =IF(B24="","",K23+G24+C24+D24+E24+F24+H24+I24) -> 3500 | L24: =K24 -> 3500
B25: ='Detailed Cash Flow'!A8 -> 45480 | C25: =IF('Detailed Cash Flow'!E8="","",'Detailed Cash Flow'!E8*-1) -> 0 | D25: =IF('Detailed Cash Flow'!F8="","",'Detailed Cash Flow'!F8*-1) -> 0 | E25: =IF('Detailed Cash Flow'!G8="","",'Detailed Cash Flow'!G8*-1) -> 0 | F25: =IF('Detailed Cash Flow'!Y8="","",'Detailed Cash Flow'!Y8*-1) -> 0 | G25: ='Detailed Cash Flow'!AJ8 -> 0 | H25: =IF('Detailed Cash Flow'!D8="","",'Detailed Cash Flow'!D8*-1) -> 0 | K25: =IF(B25="","",K24+G25+C25+D25+E25+F25+H25+I25) -> 3500 | L25: =K25 -> 3500
B26: ='Detailed Cash Flow'!A9 -> 45481 | C26: =IF('Detailed Cash Flow'!E9="","",'Detailed Cash Flow'!E9*-1) -> 0 | D26: =IF('Detailed Cash Flow'!F9="","",'Detailed Cash Flow'!F9*-1) -> 0 | E26: =IF('Detailed Cash Flow'!G9="","",'Detailed Cash Flow'!G9*-1) -> 0 | F26: =IF('Detailed Cash Flow'!Y9="","",'Detailed Cash Flow'!Y9*-1) -> 0 | G26: ='Detailed Cash Flow'!AJ9 -> 0 | H26: =IF('Detailed Cash Flow'!D9="","",'Detailed Cash Flow'!D9*-1) -> -400 | K26: =IF(B26="","",K25+G26+C26+D26+E26+F26+H26+I26) -> 3100 | L26: =K26 -> 3100
B27: ='Detailed Cash Flow'!A10 -> 45482 | C27: =IF('Detailed Cash Flow'!E10="","",'Detailed Cash Flow'!E10*-1) -> 0 | D27: =IF('Detailed Cash Flow'!F10="","",'Detailed Cash Flow'!F10*-1) -> 0 | E27: =IF('Detailed Cash Flow'!G10="","",'Detailed Cash Flow'!G10*-1) -> -500 | F27: =IF('Detailed Cash Flow'!Y10="","",'Detailed Cash Flow'!Y10*-1) -> 0 | G27: ='Detailed Cash Flow'!AJ10 -> 0 | H27: =IF('Detailed Cash Flow'!D10="","",'Detailed Cash Flow'!D10*-1) -> 0 | K27: =IF(B27="","",K26+G27+C27+D27+E27+F27+H27+I27) -> 2600 | L27: =K27 -> 2600
B28: ='Detailed Cash Flow'!A11 -> 45483 | C28: =IF('Detailed Cash Flow'!E11="","",'Detailed Cash Flow'!E11*-1) -> -500 | D28: =IF('Detailed Cash Flow'!F11="","",'Detailed Cash Flow'!F11*-1) -> 0 | E28: =IF('Detailed Cash Flow'!G11="","",'Detailed Cash Flow'!G11*-1) -> 0 | F28: =IF('Detailed Cash Flow'!Y11="","",'Detailed Cash Flow'!Y11*-1) -> 0 | G28: ='Detailed Cash Flow'!AJ11 -> 0 | H28: =IF('Detailed Cash Flow'!D11="","",'Detailed Cash Flow'!D11*-1) -> 0 | K28: =IF(B28="","",K27+G28+C28+D28+E28+F28+H28+I28) -> 2100 | L28: =K28 -> 2100
B29: ='Detailed Cash Flow'!A12 -> 45484 | C29: =IF('Detailed Cash Flow'!E12="","",'Detailed Cash Flow'!E12*-1) -> -300 | D29: =IF('Detailed Cash Flow'!F12="","",'Detailed Cash Flow'!F12*-1) -> 0 | E29: =IF('Detailed Cash Flow'!G12="","",'Detailed Cash Flow'!G12*-1) -> 0 | F29: =IF('Detailed Cash Flow'!Y12="","",'Detailed Cash Flow'!Y12*-1) -> 0 | G29: ='Detailed Cash Flow'!AJ12 -> 0 | H29: =IF('Detailed Cash Flow'!D12="","",'Detailed Cash Flow'!D12*-1) -> 0 | K29: =IF(B29="","",K28+G29+C29+D29+E29+F29+H29+I29) -> 1800 | L29: =K29 -> 1800
B30: ='Detailed Cash Flow'!A13 -> 45485 | C30: =IF('Detailed Cash Flow'!E13="","",'Detailed Cash Flow'!E13*-1) -> 0 | D30: =IF('Detailed Cash Flow'!F13="","",'Detailed Cash Flow'!F13*-1) -> 0 | E30: =IF('Detailed Cash Flow'!G13="","",'Detailed Cash Flow'!G13*-1) -> 0 | F30: =IF('Detailed Cash Flow'!Y13="","",'Detailed Cash Flow'!Y13*-1) -> 0 | G30: ='Detailed Cash Flow'!AJ13 -> 0 | H30: =IF('Detailed Cash Flow'!D13="","",'Detailed Cash Flow'!D13*-1) -> 0 | K30: =IF(B30="","",K29+G30+C30+D30+E30+F30+H30+I30) -> 1800 | L30: =K30 -> 1800
B31: ='Detailed Cash Flow'!A14 -> 45486 | C31: =IF('Detailed Cash Flow'!E14="","",'Detailed Cash Flow'!E14*-1) -> 0 | D31: =IF('Detailed Cash Flow'!F14="","",'Detailed Cash Flow'!F14*-1) -> 0 | E31: =IF('Detailed Cash Flow'!G14="","",'Detailed Cash Flow'!G14*-1) -> 0 | F31: =IF('Detailed Cash Flow'!Y14="","",'Detailed Cash Flow'!Y14*-1) -> 0 | G31: ='Detailed Cash Flow'!AJ14 -> 0 | H31: =IF('Detailed Cash Flow'!D14="","",'Detailed Cash Flow'!D14*-1) -> 0 | K31: =IF(B31="","",K30+G31+C31+D31+E31+F31+H31+I31) -> 1800 | L31: =K31 -> 1800
... B1483: ='Detailed Cash Flow'!A1466 | C1483: =IF('Detailed Cash Flow'!E1466="","",'Detailed Cash Flow'!E1466*-1) | D1483: =IF('Detailed Cash Flow'!F1466="","",'Detailed Cash Flow'!F1466*-1) | E1483: =IF('Detailed Cash Flow'!G1466="","",'Detailed Cash Flow'!G1466*-1) | F1483: =IF('Detailed Cash Flow'!Y1466="","",'Detailed Cash Flow'!Y1466*-1) | G1483: ='Detailed Cash Flow'!AJ1466 | H1483: =IF('Detailed Cash Flow'!D1466="","",'Detailed Cash Flow'!D1466*-1) | K1483: =IF(B1483="","",K1482+G1483+C1483+D1483+E1483+F1483+H1483+I1483) | L1483: =K1483

Sheet 5) Next Steps
E2: Congratulations on making it this far in your budgeting journey!
B8: 5) Next Steps:
B9: * Tracking
B10: This spreadsheet is unique because its main purpose is to figure out a weekly allowance that will work for your specific financial situation.
B13: Your next step is to start tracking what you spend to make sure you stay within your weekly allowance (your Happy Money). You won't do that in this spreadsheet. You can do that however you like. We suggest using our free app!
B16: Download Our New App!
B18: * Donate
B19: We are a nonprofit. Any donation helps!
B24: * More Help
B25: Please email us with any questions. Help is always free! | G25: Hello@HappyGiraffe.org
B26: Our website has video tutorials and other resources. | G26: HappyGiraffe.org
B27: Our book is also available on Amazon! | G27: Buy Our Book
G28: Download The App

Sheet Detailed Cash Flow
A1: Date | B1: End of Month | C1: Weekend | D1: Weekly Extra | E1: Monthly exp | F1: Yearly exp | G1: One-Time exp | H1: Weekly | I1: Every Other Week | J1: 1st And 15th | K1: 2nd Wednesday | L1: 3rd Wednesday | M1: 4th Wednesday | N1: Every 4 Weeks | O1: Every 6 Weeks | P1: Every 8 Weeks | Q1: Monthly | R1: Every 2 Months | S1: Every 3 Months | T1: Every 4 Months | U1: Every 6 Months | V1: Yearly | W1: One-Time | X1: Expense sum | Y1: Other Sum | Z1: Weekly inc | AA1: Every Other Week inc | AB1: 1st and 15th inc | AC1: 2nd Wed inc | AD1: 3rd Wed inc | AE1: 4th Wed inc | AF1: Every 4 wks | AG1: Monthly inc | AH1: Yearly inc | AI1: One-Time inc | AJ1: Income sum
A2: ='1) Period'!E18 -> 45474 | B2: =IF(DAY(A2)>DAY(A2+1),"Y","N") -> N | C2: =IF(WEEKDAY(A2,2)>5,"Y","F") -> F | D2: =IF(A2="","",IF('4) Happy Money'!H28=0,WAllowance,ROUND((WAllowance/7)*'4) Happy Money'!H28,2))) -> 400 | E2: =IF(A2="","",IF(B2="N",SUMIF(TMonthly[Day of the Month],DAY(A2),TMonthly[Amount]),SUMIF(TMonthly[Day of the Month],">="&DAY(A2),TMonthly[Amount]))) -> 195 | F2: {=IF(A2="","",SUMPRODUCT(--(TYearly[Due Date]<=A2),IF(B2="N",--(TYearly[Day]=DAY(A2)),--(TYearly[Day]>=DAY(A2))),--(IFERROR(MOD(TYearly[Month]-MONTH(A2)+12,12),1)=0),TYearly[Amount]))} -> 0 | G2: =IF(A2="","",SUMIF(TOneTime[Due Date],A2,TOneTime[Amount])) -> 0 | H2: {=IF(A2="","",IF(COUNTIF(TOther[Frequency],$H$1)=0,0,SUMPRODUCT(--(IFERROR(MOD(A2-TOther[Start Date],7),1)=0),--(TOther[Frequency]=$H$1),--(TOther[Start Date]<=A2),--(TOther[End Date Calc]>=A2),TOther[Amount])))} -> 0 | I2: {=IF(A2="","",IF(COUNTIF(TOther[Frequency],$I$1)=0,0,SUMPRODUCT(--(IFERROR(MOD(A2-TOther[Start Date],14),1)=0),--(TOther[Frequency]=$I$1),--(TOther[Start Date]<=A2),--(TOther[End Date Calc]>=A2),TOther[Amount])))} -> 0 | J2: =IF(A2="","",IF(COUNTIF(TOther[Frequency],$J$1)=0,0,IF(OR(DAY(A2)=1,DAY(A2)=15),SUMIFS(TOther[Amount],TOther[Frequency],$J$1,TOther[Start Date],"<="&$A2,TOther[End Date Calc],">="&A2),0))) -> 0 | K2: =IF(A2="","",IF(COUNTIF(TOther[Frequency],$K$1)=0,0,IF(A2=(A2-DAY(A2)+1+2*7-WEEKDAY(A2-DAY(A2)+8-4,1)),SUMIFS(TOther[Amount],TOther[Frequency],$K$1,TOther[Start Date],"<="&$A2,TOther[End Date Calc],">="&A2),0))) -> 0 | L2: =IF(A2="","",IF(COUNTIF(TOther[Frequency],$L$1)=0,0,IF(A2=(A2-DAY(A2)+1+3*7-WEEKDAY(A2-DAY(A2)+8-4,1)),SUMIFS(TOther[Amount],TOther[Frequency],$L$1,TOther[Start Date],"<="&$A2,TOther[End Date Calc],">="&A2),0))) -> 0 | M2: =IF(A2="","",IF(COUNTIF(TOther[Frequency],$M$1)=0,0,IF(A2=(A2-DAY(A2)+1+4*7-WEEKDAY(A2-DAY(A2)+8-4,1)),SUMIFS(TOther[Amount],TOther[Frequency],$M$1,TOther[Start Date],"<="&$A2,TOther[End Date Calc],">="&A2),0))) -> 0 | N2: {=IF(A2="","",IF(COUNTIF(TOther[Frequency],$N$1)=0,0,SUMPRODUCT(--(IFERROR(MOD(A2-TOther[Start Date],28),1)=0),--(TOther[Frequency]=$N$1),--(TOther[Start Date]<=A2),--(TOther[End Date Calc]>=A2),TOther[Amount])))} -> 0 | O2: {=IF(A2="","",IF(COUNTIF(TOther[Frequency],$O$1)=0,0,SUMPRODUCT(--(IFERROR(MOD(A2-TOther[Start Date],42),1)=0),--(TOther[Frequency]=$O$1),--(TOther[Start Date]<=A2),--(TOther[End Date Calc]>=A2),TOther[Amount])))} -> 0 | P2: {=IF(A2="","",IF(COUNTIF(TOther[Frequency],$P$1)=0,0,SUMPRODUCT(--(IFERROR(MOD(A2-TOther[Start Date],56),1)=0),--(TOther[Frequency]=$P$1),--(TOther[Start Date]<=A2),--(TOther[End Date Calc]>=A2),TOther[Amount])))} -> 0 | Q2: =IF(A2="","",IF(COUNTIF(TOther[Frequency],$Q$1)=0,0,IF(B2="N",SUMIFS(TOther[Amount],TOther[Frequency],$Q$1,TOther[Start Date],"<="&$A2,TOther[End Date Calc],">="&A2,TOther[Start Day],DAY(A2)),SUMIFS(TOther[Amount],TOther[Frequency],$Q$1,TOther[Start Date],"<="&$A2,TOther[End Date Calc],">="&A2,TOther[Start Day],">="&DAY(A2))))) -> 0 | R2: {=IF(A2="","",IF(COUNTIF(TOther[Frequency],R$1)=0,0,SUMPRODUCT(--(TOther[Frequency]=R$1),--(TOther[Start Date]<=A2),--(TOther[End Date Calc]>=A2),IF(B2="N",--(TOther[Start Day]=DAY(A2)),--(TOther[Start Day]>=DAY(A2))),--(IFERROR(MOD(TOther[Start Month]-MONTH(A2)+2,2),1)=0),TOther[Amount])))} -> 0 | S2: {=IF(A2="","",IF(COUNTIF(TOther[Frequency],S$1)=0,0,SUMPRODUCT(--(TOther[Frequency]=S$1),--(TOther[Start Date]<=A2),--(TOther[End Date Calc]>=A2),IF(B2="N",--(TOther[Start Day]=DAY(A2)),--(TOther[Start Day]>=DAY(A2))),--(IFERROR(MOD(TOther[Start Month]-MONTH(A2)+3,3),1)=0),TOther[Amount])))} -> 0 | T2: {=IF($A2="","",IF(COUNTIF(TOther[Frequency],T$1)=0,0,SUMPRODUCT(--(TOther[Frequency]=T$1),--(TOther[Start Date]<=$A2),--(TOther[End Date Calc]>=$A2),IF($B2="N",--(TOther[Start Day]=DAY($A2)),--(TOther[Start Day]>=DAY($A2))),--(IFERROR(MOD(TOther[Start Month]-MONTH($A2)+4,4),1)=0),TOther[Amount])))} -> 0 | U2: {=IF(A2="","",IF(COUNTIF(TOther[Frequency],U$1)=0,0,SUMPRODUCT(--(TOther[Frequency]=U$1),--(TOther[Start Date]<=A2),--(TOther[End Date Calc]>=A2),IF(B2="N",--(TOther[Start Day]=DAY(A2)),--(TOther[Start Day]>=DAY(A2))),--(IFERROR(MOD(TOther[Start Month]-MONTH(A2)+6,6),1)=0),TOther[Amount])))} -> 0 | V2: {=IF(A2="","",IF(COUNTIF(TOther[Frequency],V$1)=0,0,SUMPRODUCT(--(TOther[Frequency]=V$1),--(TOther[Start Date]<=A2),--(TOther[End Date Calc]>=A2),IF(B2="N",--(TOther[Start Day]=DAY(A2)),--(TOther[Start Day]>=DAY(A2))),--(IFERROR(MOD(TOther[Start Month]-MONTH(A2)+12,12),1)=0),TOther[Amount])))} -> 0 | W2: =IF(A2="","",IF(COUNTIF(TOther[Frequency],W$1)=0,0,SUMIFS(TOther[Amount],TOther[Start Date],A2,TOther[Frequency],W$1))) -> 0 | X2: =IF(A2="","",SUM(E2:W2)) -> 195 | Y2: =IF(A2="","",SUM(H2:W2)) -> 0 | Z2: {=IF(A2="","",IF(COUNTIF('2) Income'!$D$13:$D$32,"Weekly")=0,0,SUMPRODUCT(--(IFERROR(MOD(A2-'2) Income'!$F$13:$F$32,7),1)=0),--('2) Income'!$D$13:$D$32="Weekly"),--('2) Income'!$F$13:$F$32<=A2),'2) Income'!$E$13:$E$32)))} -> 0 | AA2: {=IF(A2="","",IF(COUNTIF('2) Income'!$D$13:$D$32,"Every Other Week")=0,0,SUMPRODUCT(--(IFERROR(MOD(A2-'2) Income'!$F$13:$F$32,14),1)=0),--('2) Income'!$D$13:$D$32="Every Other Week"),--('2) Income'!$F$13:$F$32<=A2),'2) Income'!$E$13:$E$32)))} -> 0 | AB2: =IF(A2="","",IF(COUNTIF('2) Income'!$D$13:$D$32,"1st and 15th")=0,0,IF(OR(DAY(A2)=1,DAY(A2)=15),SUMIFS('2) Income'!$E$13:$E$32,'2) Income'!$D$13:$D$32,"1st and 15th",'2) Income'!$F$13:$F$32,"<="&$A2),0))) -> 0 | AC2: =IF(A2="","",IF(COUNTIF('2) Income'!$D$13:$D$32,"2nd Wednesday")=0,0,IF(A2=(A2-DAY(A2)+1+2*7-WEEKDAY(A2-DAY(A2)+8-4,1)),SUMIFS('2) Income'!$E$13:$E$32,'2) Income'!$D$13:$D$32,"2nd Wednesday",'2) Income'!$F$13:$F$32,"<="&$A2),0))) -> 0 | AD2: =IF(A2="","",IF(COUNTIF('2) Income'!$D$13:$D$32,"3rd Wednesday")=0,0,IF(A2=(A2-DAY(A2)+1+3*7-WEEKDAY(A2-DAY(A2)+8-4,1)),SUMIFS('2) Income'!$E$13:$E$32,'2) Income'!$D$13:$D$32,"3rd Wednesday",'2) Income'!$F$13:$F$32,"<="&$A2),0))) -> 0 | AE2: =IF(A2="","",IF(COUNTIF('2) Income'!$D$13:$D$32,"4th Wednesday")=0,0,IF(A2=(A2-DAY(A2)+1+4*7-WEEKDAY(A2-DAY(A2)+8-4,1)),SUMIFS('2) Income'!$E$13:$E$32,'2) Income'!$D$13:$D$32,"4th Wednesday",'2) Income'!$F$13:$F$32,"<="&$A2),0))) -> 0 | AF2: {=IF(A2="","",IF(COUNTIF('2) Income'!$D$13:$D$32,"Every 4 Weeks")=0,0,SUMPRODUCT(--(IFERROR(MOD(A2-'2) Income'!$F$13:$F$32,28),1)=0),--('2) Income'!$D$13:$D$32="Every 4 Weeks"),--('2) Income'!$F$13:$F$32<=A2),'2) Income'!$E$13:$E$32)))} -> 0 | AG2: =IF(A2="","",IF(COUNTIF('2) Income'!$D$13:$D$32,"Monthly")=0,0,IF(B2="N",SUMIFS('2) Income'!$E$13:$E$32,'2) Income'!$D$13:$D$32,"monthly",'2) Income'!$F$13:$F$32,"<="&$A2,'2) Income'!$I$13:$I$32,DAY(A2)),SUMIFS('2) Income'!$E$13:$E$32,'2) Income'!$D$13:$D$32,"monthly",'2) Income'!$F$13:$F$32,"<="&$A2,'2) Income'!$I$13:$I$32,">="&DAY(A2))))) -> 650 | AH2: {=IF(A2="","",IF(COUNTIF('2) Income'!$D$13:$D$32,"Yearly")=0,0,SUMPRODUCT(--('2) Income'!$D$13:$D$32="Yearly"),--('2) Income'!$F$13:$F$32<=A2),IF(B2="N",--('2) Income'!$I$13:$I$32=DAY(A2)),--('2) Income'!$I$13:$I$32>=DAY(A2))),--(IFERROR(MOD('2) Income'!$H$13:$H$32-MONTH(A2)+12,12),1)=0),'2) Income'!$E$13:$E$32)))} -> 0 | AI2: =IF(A2="","",IF(COUNTIF('2) Income'!$D$13:$D$32,"one-time")=0,0,SUMIFS('2) Income'!$E$13:$E$32,'2) Income'!$D$13:$D$32,"one-time",'2) Income'!$F$13:$F$32,"="&$A2))) -> 0 | AJ2: =IF(A2="","",SUM(Z2:AI2)) -> 650 | AL2: Monthly Income Original
A3: =IF(A2="","",IF(A2+1<='1) Period'!$E$21,A2+1,"")) -> 45475 | B3: =IF(DAY(A3)>DAY(A3+1),"Y","N") -> N | C3: =IF(WEEKDAY(A3,2)>5,"Y","F") -> F | D3: =IF(A3="","",IF(TEXT(A3,"dddd")='4) Happy Money'!$E$23,WAllowance,0)) -> 0 | E3: =IF(A3="","",IF(B3="N",SUMIF(TMonthly[Day of the Month],DAY(A3),TMonthly[Amount]),SUMIF(TMonthly[Day of the Month],">="&DAY(A3),TMonthly[Amount]))) -> 35 | F3: {=IF(A3="","",SUMPRODUCT(--(TYearly[Due Date]<=A3),IF(B3="N",--(TYearly[Day]=DAY(A3)),--(TYearly[Day]>=DAY(A3))),--(IFERROR(MOD(TYearly[Month]-MONTH(A3)+12,12),1)=0),TYearly[Amount]))} -> 0 | G3: =IF(A3="","",SUMIF(TOneTime[Due Date],A3,TOneTime[Amount])) -> 0 | H3: {=IF(A3="","",IF(COUNTIF(TOther[Frequency],$H$1)=0,0,SUMPRODUCT(--(IFERROR(MOD(A3-TOther[Start Date],7),1)=0),--(TOther[Frequency]=$H$1),--(TOther[Start Date]<=A3),--(TOther[End Date Calc]>=A3),TOther[Amount])))} -> 0 | I3: {=IF(A3="","",IF(COUNTIF(TOther[Frequency],$I$1)=0,0,SUMPRODUCT(--(IFERROR(MOD(A3-TOther[Start Date],14),1)=0),--(TOther[Frequency]=$I$1),--(TOther[Start Date]<=A3),--(TOther[End Date Calc]>=A3),TOther[Amount])))} -> 0 | J3: =IF(A3="","",IF(COUNTIF(TOther[Frequency],$J$1)=0,0,IF(OR(DAY(A3)=1,DAY(A3)=15),SUMIFS(TOther[Amount],TOther[Frequency],$J$1,TOther[Start Date],"<="&$A3,TOther[End Date Calc],">="&A3),0))) -> 0 | K3: =IF(A3="","",IF(COUNTIF(TOther[Frequency],$K$1)=0,0,IF(A3=(A3-DAY(A3)+1+2*7-WEEKDAY(A3-DAY(A3)+8-4,1)),SUMIFS(TOther[Amount],TOther[Frequency],$K$1,TOther[Start Date],"<="&$A3,TOther[End Date Calc],">="&A3),0))) -> 0 | L3: =IF(A3="","",IF(COUNTIF(TOther[Frequency],$L$1)=0,0,IF(A3=(A3-DAY(A3)+1+3*7-WEEKDAY(A3-DAY(A3)+8-4,1)),SUMIFS(TOther[Amount],TOther[Frequency],$L$1,TOther[Start Date],"<="&$A3,TOther[End Date Calc],">="&A3),0))) -> 0 | M3: =IF(A3="","",IF(COUNTIF(TOther[Frequency],$M$1)=0,0,IF(A3=(A3-DAY(A3)+1+4*7-WEEKDAY(A3-DAY(A3)+8-4,1)),SUMIFS(TOther[Amount],TOther[Frequency],$M$1,TOther[Start Date],"<="&$A3,TOther[End Date Calc],">="&A3),0))) -> 0 | N3: {=IF(A3="","",IF(COUNTIF(TOther[Frequency],$N$1)=0,0,SUMPRODUCT(--(IFERROR(MOD(A3-TOther[Start Date],28),1)=0),--(TOther[Frequency]=$N$1),--(TOther[Start Date]<=A3),--(TOther[End Date Calc]>=A3),TOther[Amount])))} -> 0 | O3: {=IF(A3="","",IF(COUNTIF(TOther[Frequency],$O$1)=0,0,SUMPRODUCT(--(IFERROR(MOD(A3-TOther[Start Date],42),1)=0),--(TOther[Frequency]=$O$1),--(TOther[Start Date]<=A3),--(TOther[End Date Calc]>=A3),TOther[Amount])))} -> 0 | P3: {=IF(A3="","",IF(COUNTIF(TOther[Frequency],$P$1)=0,0,SUMPRODUCT(--(IFERROR(MOD(A3-TOther[Start Date],56),1)=0),--(TOther[Frequency]=$P$1),--(TOther[Start Date]<=A3),--(TOther[End Date Calc]>=A3),TOther[Amount])))} -> 0 | Q3: =IF(A3="","",IF(COUNTIF(TOther[Frequency],$Q$1)=0,0,IF(B3="N",SUMIFS(TOther[Amount],TOther[Frequency],$Q$1,TOther[Start Date],"<="&$A3,TOther[End Date Calc],">="&A3,TOther[Start Day],DAY(A3)),SUMIFS(TOther[Amount],TOther[Frequency],$Q$1,TOther[Start Date],"<="&$A3,TOther[End Date Calc],">="&A3,TOther[Start Day],">="&DAY(A3))))) -> 0 | R3: {=IF(A3="","",IF(COUNTIF(TOther[Frequency],R$1)=0,0,SUMPRODUCT(--(TOther[Frequency]=R$1),--(TOther[Start Date]<=A3),--(TOther[End Date Calc]>=A3),IF(B3="N",--(TOther[Start Day]=DAY(A3)),--(TOther[Start Day]>=DAY(A3))),--(IFERROR(MOD(TOther[Start Month]-MONTH(A3)+2,2),1)=0),TOther[Amount])))} -> 0 | S3: {=IF(A3="","",IF(COUNTIF(TOther[Frequency],S$1)=0,0,SUMPRODUCT(--(TOther[Frequency]=S$1),--(TOther[Start Date]<=A3),--(TOther[End Date Calc]>=A3),IF(B3="N",--(TOther[Start Day]=DAY(A3)),--(TOther[Start Day]>=DAY(A3))),--(IFERROR(MOD(TOther[Start Month]-MONTH(A3)+3,3),1)=0),TOther[Amount])))} -> 0 | T3: {=IF($A3="","",IF(COUNTIF(TOther[Frequency],T$1)=0,0,SUMPRODUCT(--(TOther[Frequency]=T$1),--(TOther[Start Date]<=$A3),--(TOther[End Date Calc]>=$A3),IF($B3="N",--(TOther[Start Day]=DAY($A3)),--(TOther[Start Day]>=DAY($A3))),--(IFERROR(MOD(TOther[Start Month]-MONTH($A3)+4,4),1)=0),TOther[Amount])))} -> 0 | U3: {=IF(A3="","",IF(COUNTIF(TOther[Frequency],$U$1)=0,0,SUMPRODUCT(--(TOther[Frequency]=$U$1),--(TOther[Start Date]<=A3),--(TOther[End Date Calc]>=A3),IF(B3="N",--(TOther[Start Day]=DAY(A3)),--(TOther[Start Day]>=DAY(A3))),--(IFERROR(MOD(TOther[Start Month]-MONTH(A3)+6,6),1)=0),TOther[Amount])))} -> 0 | V3: {=IF(A3="","",IF(COUNTIF(TOther[Frequency],$V$1)=0,0,SUMPRODUCT(--(TOther[Frequency]=$V$1),--(TOther[Start Date]<=A3),--(TOther[End Date Calc]>=A3),IF(B3="N",--(TOther[Start Day]=DAY(A3)),--(TOther[Start Day]>=DAY(A3))),--(IFERROR(MOD(TOther[Start Month]-MONTH(A3)+12,12),1)=0),TOther[Amount])))} -> 0 | W3: =IF(A3="","",SUMIFS(TOther[Amount],TOther[Start Date],A3,TOther[Frequency],$W$1)) -> 0 | X3: =IF(A3="","",SUM(E3:W3)) -> 35 | Y3: =IF(A3="","",SUM(H3:W3)) -> 0 | Z3: {=IF(A3="","",IF(COUNTIF('2) Income'!$D$13:$D$32,"Weekly")=0,0,SUMPRODUCT(--(IFERROR(MOD(A3-'2) Income'!$F$13:$F$32,7),1)=0),--('2) Income'!$D$13:$D$32="Weekly"),--('2) Income'!$F$13:$F$32<=A3),'2) Income'!$E$13:$E$32)))} -> 0 | AA3: {=IF(A3="","",IF(COUNTIF('2) Income'!$D$13:$D$32,"Every Other Week")=0,0,SUMPRODUCT(--(IFERROR(MOD(A3-'2) Income'!$F$13:$F$32,14),1)=0),--('2) Income'!$D$13:$D$32="Every Other Week"),--('2) Income'!$F$13:$F$32<=A3),'2) Income'!$E$13:$E$32)))} -> 0 | AB3: =IF(A3="","",IF(COUNTIF('2) Income'!$D$13:$D$32,"1st and 15th")=0,0,IF(OR(DAY(A3)=1,DAY(A3)=15),SUMIFS('2) Income'!$E$13:$E$32,'2) Income'!$D$13:$D$32,"1st and 15th",'2) Income'!$F$13:$F$32,"<="&$A3),0))) -> 0 | AC3: =IF(A3="","",IF(COUNTIF('2) Income'!$D$13:$D$32,"2nd Wednesday")=0,0,IF(A3=(A3-DAY(A3)+1+2*7-WEEKDAY(A3-DAY(A3)+8-4,1)),SUMIFS('2) Income'!$E$13:$E$32,'2) Income'!$D$13:$D$32,"2nd Wednesday",'2) Income'!$F$13:$F$32,"<="&$A3),0))) -> 0 | AD3: =IF(A3="","",IF(COUNTIF('2) Income'!$D$13:$D$32,"3rd Wednesday")=0,0,IF(A3=(A3-DAY(A3)+1+3*7-WEEKDAY(A3-DAY(A3)+8-4,1)),SUMIFS('2) Income'!$E$13:$E$32,'2) Income'!$D$13:$D$32,"3rd Wednesday",'2) Income'!$F$13:$F$32,"<="&$A3),0))) -> 0 | AE3: =IF(A3="","",IF(COUNTIF('2) Income'!$D$13:$D$32,"4th Wednesday")=0,0,IF(A3=(A3-DAY(A3)+1+4*7-WEEKDAY(A3-DAY(A3)+8-4,1)),SUMIFS('2) Income'!$E$13:$E$32,'2) Income'!$D$13:$D$32,"4th Wednesday",'2) Income'!$F$13:$F$32,"<="&$A3),0))) -> 0 | AF3: {=IF(A3="","",IF(COUNTIF('2) Income'!$D$13:$D$32,"Every 4 Weeks")=0,0,SUMPRODUCT(--(IFERROR(MOD(A3-'2) Income'!$F$13:$F$32,28),1)=0),--('2) Income'!$D$13:$D$32="Every 4 Weeks"),--('2) Income'!$F$13:$F$32<=A3),'2) Income'!$E$13:$E$32)))} -> 0 | AG3: =IF(A3="","",IF(COUNTIF('2) Income'!$D$13:$D$32,"Monthly")=0,0,IF(B3="N",SUMIFS('2) Income'!$E$13:$E$32,'2) Income'!$D$13:$D$32,"monthly",'2) Income'!$F$13:$F$32,"<="&$A3,'2) Income'!$I$13:$I$32,DAY(A3)),SUMIFS('2) Income'!$E$13:$E$32,'2) Income'!$D$13:$D$32,"monthly",'2) Income'!$F$13:$F$32,"<="&$A3,'2) Income'!$I$13:$I$32,">="&DAY(A3))))) -> 0 | AH3: {=IF(A3="","",IF(COUNTIF('2) Income'!$D$13:$D$32,"Yearly")=0,0,SUMPRODUCT(--('2) Income'!$D$13:$D$32="Yearly"),--('2) Income'!$F$13:$F$32<=A3),IF(B3="N",--('2) Income'!$I$13:$I$32=DAY(A3)),--('2) Income'!$I$13:$I$32>=DAY(A3))),--(IFERROR(MOD('2) Income'!$H$13:$H$32-MONTH(A3)+12,12),1)=0),'2) Income'!$E$13:$E$32)))} -> 0 | AI3: =IF(A3="","",IF(COUNTIF('2) Income'!$D$13:$D$32,"one-time")=0,0,SUMIFS('2) Income'!$E$13:$E$32,'2) Income'!$D$13:$D$32,"one-time",'2) Income'!$F$13:$F$32,"="&$A3))) -> 0 | AJ3: =IF(A3="","",SUM(Z3:AI3)) -> 0 | AL3: Day | AM3: We has a column called this in column V
A4: =IF(A3="","",IF(A3+1<='1) Period'!$E$21,A3+1,"")) -> 45476 | B4: =IF(DAY(A4)>DAY(A4+1),"Y","N") -> N | C4: =IF(WEEKDAY(A4,2)>5,"Y","F") -> F | D4: =IF(A4="","",IF(TEXT(A4,"dddd")='4) Happy Money'!$E$23,WAllowance,0)) -> 0 | E4: =IF(A4="","",IF(B4="N",SUMIF(TMonthly[Day of the Month],DAY(A4),TMonthly[Amount]),SUMIF(TMonthly[Day of the Month],">="&DAY(A4),TMonthly[Amount]))) -> 35 | F4: {=IF(A4="","",SUMPRODUCT(--(TYearly[Due Date]<=A4),IF(B4="N",--(TYearly[Day]=DAY(A4)),--(TYearly[Day]>=DAY(A4))),--(IFERROR(MOD(TYearly[Month]-MONTH(A4)+12,12),1)=0),TYearly[Amount]))} -> 0 | G4: =IF(A4="","",SUMIF(TOneTime[Due Date],A4,TOneTime[Amount])) -> 0 | H4: {=IF(A4="","",IF(COUNTIF(TOther[Frequency],$H$1)=0,0,SUMPRODUCT(--(IFERROR(MOD(A4-TOther[Start Date],7),1)=0),--(TOther[Frequency]=$H$1),--(TOther[Start Date]<=A4),--(TOther[End Date Calc]>=A4),TOther[Amount])))} -> 0 | I4: {=IF(A4="","",IF(COUNTIF(TOther[Frequency],$I$1)=0,0,SUMPRODUCT(--(IFERROR(MOD(A4-TOther[Start Date],14),1)=0),--(TOther[Frequency]=$I$1),--(TOther[Start Date]<=A4),--(TOther[End Date Calc]>=A4),TOther[Amount])))} -> 0 | J4: =IF(A4="","",IF(COUNTIF(TOther[Frequency],$J$1)=0,0,IF(OR(DAY(A4)=1,DAY(A4)=15),SUMIFS(TOther[Amount],TOther[Frequency],$J$1,TOther[Start Date],"<="&$A4,TOther[End Date Calc],">="&A4),0))) -> 0 | K4: =IF(A4="","",IF(COUNTIF(TOther[Frequency],$K$1)=0,0,IF(A4=(A4-DAY(A4)+1+2*7-WEEKDAY(A4-DAY(A4)+8-4,1)),SUMIFS(TOther[Amount],TOther[Frequency],$K$1,TOther[Start Date],"<="&$A4,TOther[End Date Calc],">="&A4),0))) -> 0 | L4: =IF(A4="","",IF(COUNTIF(TOther[Frequency],$L$1)=0,0,IF(A4=(A4-DAY(A4)+1+3*7-WEEKDAY(A4-DAY(A4)+8-4,1)),SUMIFS(TOther[Amount],TOther[Frequency],$L$1,TOther[Start Date],"<="&$A4,TOther[End Date Calc],">="&A4),0))) -> 0 | M4: =IF(A4="","",IF(COUNTIF(TOther[Frequency],$M$1)=0,0,IF(A4=(A4-DAY(A4)+1+4*7-WEEKDAY(A4-DAY(A4)+8-4,1)),SUMIFS(TOther[Amount],TOther[Frequency],$M$1,TOther[Start Date],"<="&$A4,TOther[End Date Calc],">="&A4),0))) -> 0 | N4: {=IF(A4="","",IF(COUNTIF(TOther[Frequency],$N$1)=0,0,SUMPRODUCT(--(IFERROR(MOD(A4-TOther[Start Date],28),1)=0),--(TOther[Frequency]=$N$1),--(TOther[Start Date]<=A4),--(TOther[End Date Calc]>=A4),TOther[Amount])))} -> 0 | O4: {=IF(A4="","",IF(COUNTIF(TOther[Frequency],$O$1)=0,0,SUMPRODUCT(--(IFERROR(MOD(A4-TOther[Start Date],42),1)=0),--(TOther[Frequency]=$O$1),--(TOther[Start Date]<=A4),--(TOther[End Date Calc]>=A4),TOther[Amount])))} -> 0 | P4: {=IF(A4="","",IF(COUNTIF(TOther[Frequency],$P$1)=0,0,SUMPRODUCT(--(IFERROR(MOD(A4-TOther[Start Date],56),1)=0),--(TOther[Frequency]=$P$1),--(TOther[Start Date]<=A4),--(TOther[End Date Calc]>=A4),TOther[Amount])))} -> 0 | Q4: =IF(A4="","",IF(COUNTIF(TOther[Frequency],$Q$1)=0,0,IF(B4="N",SUMIFS(TOther[Amount],TOther[Frequency],$Q$1,TOther[Start Date],"<="&$A4,TOther[End Date Calc],">="&A4,TOther[Start Day],DAY(A4)),SUMIFS(TOther[Amount],TOther[Frequency],$Q$1,TOther[Start Date],"<="&$A4,TOther[End Date Calc],">="&A4,TOther[Start Day],">="&DAY(A4))))) -> 0 | R4: {=IF(A4="","",IF(COUNTIF(TOther[Frequency],R$1)=0,0,SUMPRODUCT(--(TOther[Frequency]=R$1),--(TOther[Start Date]<=A4),--(TOther[End Date Calc]>=A4),IF(B4="N",--(TOther[Start Day]=DAY(A4)),--(TOther[Start Day]>=DAY(A4))),--(IFERROR(MOD(TOther[Start Month]-MONTH(A4)+2,2),1)=0),TOther[Amount])))} -> 0 | S4: {=IF(A4="","",IF(COUNTIF(TOther[Frequency],S$1)=0,0,SUMPRODUCT(--(TOther[Frequency]=S$1),--(TOther[Start Date]<=A4),--(TOther[End Date Calc]>=A4),IF(B4="N",--(TOther[Start Day]=DAY(A4)),--(TOther[Start Day]>=DAY(A4))),--(IFERROR(MOD(TOther[Start Month]-MONTH(A4)+3,3),1)=0),TOther[Amount])))} -> 0 | T4: {=IF($A4="","",IF(COUNTIF(TOther[Frequency],T$1)=0,0,SUMPRODUCT(--(TOther[Frequency]=T$1),--(TOther[Start Date]<=$A4),--(TOther[End Date Calc]>=$A4),IF($B4="N",--(TOther[Start Day]=DAY($A4)),--(TOther[Start Day]>=DAY($A4))),--(IFERROR(MOD(TOther[Start Month]-MONTH($A4)+4,4),1)=0),TOther[Amount])))} -> 0 | U4: {=IF(A4="","",IF(COUNTIF(TOther[Frequency],$U$1)=0,0,SUMPRODUCT(--(TOther[Frequency]=$U$1),--(TOther[Start Date]<=A4),--(TOther[End Date Calc]>=A4),IF(B4="N",--(TOther[Start Day]=DAY(A4)),--(TOther[Start Day]>=DAY(A4))),--(IFERROR(MOD(TOther[Start Month]-MONTH(A4)+6,6),1)=0),TOther[Amount])))} -> 0 | V4: {=IF(A4="","",IF(COUNTIF(TOther[Frequency],$V$1)=0,0,SUMPRODUCT(--(TOther[Frequency]=$V$1),--(TOther[Start Date]<=A4),--(TOther[End Date Calc]>=A4),IF(B4="N",--(TOther[Start Day]=DAY(A4)),--(TOther[Start Day]>=DAY(A4))),--(IFERROR(MOD(TOther[Start Month]-MONTH(A4)+12,12),1)=0),TOther[Amount])))} -> 0 | W4: =IF(A4="","",SUMIFS(TOther[Amount],TOther[Start Date],A4,TOther[Frequency],$W$1)) -> 0 | X4: =IF(A4="","",SUM(E4:W4)) -> 35 | Y4: =IF(A4="","",SUM(H4:W4)) -> 0 | Z4: {=IF(A4="","",IF(COUNTIF('2) Income'!$D$13:$D$32,"Weekly")=0,0,SUMPRODUCT(--(IFERROR(MOD(A4-'2) Income'!$F$13:$F$32,7),1)=0),--('2) Income'!$D$13:$D$32="Weekly"),--('2) Income'!$F$13:$F$32<=A4),'2) Income'!$E$13:$E$32)))} -> 0 | AA4: {=IF(A4="","",IF(COUNTIF('2) Income'!$D$13:$D$32,"Every Other Week")=0,0,SUMPRODUCT(--(IFERROR(MOD(A4-'2) Income'!$F$13:$F$32,14),1)=0),--('2) Income'!$D$13:$D$32="Every Other Week"),--('2) Income'!$F$13:$F$32<=A4),'2) Income'!$E$13:$E$32)))} -> 0 | AB4: =IF(A4="","",IF(COUNTIF('2) Income'!$D$13:$D$32,"1st and 15th")=0,0,IF(OR(DAY(A4)=1,DAY(A4)=15),SUMIFS('2) Income'!$E$13:$E$32,'2) Income'!$D$13:$D$32,"1st and 15th",'2) Income'!$F$13:$F$32,"<="&$A4),0))) -> 0 | AC4: =IF(A4="","",IF(COUNTIF('2) Income'!$D$13:$D$32,"2nd Wednesday")=0,0,IF(A4=(A4-DAY(A4)+1+2*7-WEEKDAY(A4-DAY(A4)+8-4,1)),SUMIFS('2) Income'!$E$13:$E$32,'2) Income'!$D$13:$D$32,"2nd Wednesday",'2) Income'!$F$13:$F$32,"<="&$A4),0))) -> 0 | AD4: =IF(A4="","",IF(COUNTIF('2) Income'!$D$13:$D$32,"3rd Wednesday")=0,0,IF(A4=(A4-DAY(A4)+1+3*7-WEEKDAY(A4-DAY(A4)+8-4,1)),SUMIFS('2) Income'!$E$13:$E$32,'2) Income'!$D$13:$D$32,"3rd Wednesday",'2) Income'!$F$13:$F$32,"<="&$A4),0))) -> 0 | AE4: =IF(A4="","",IF(COUNTIF('2) Income'!$D$13:$D$32,"4th Wednesday")=0,0,IF(A4=(A4-DAY(A4)+1+4*7-WEEKDAY(A4-DAY(A4)+8-4,1)),SUMIFS('2) Income'!$E$13:$E$32,'2) Income'!$D$13:$D$32,"4th Wednesday",'2) Income'!$F$13:$F$32,"<="&$A4),0))) -> 0 | AF4: {=IF(A4="","",IF(COUNTIF('2) Income'!$D$13:$D$32,"Every 4 Weeks")=0,0,SUMPRODUCT(--(IFERROR(MOD(A4-'2) Income'!$F$13:$F$32,28),1)=0),--('2) Income'!$D$13:$D$32="Every 4 Weeks"),--('2) Income'!$F$13:$F$32<=A4),'2) Income'!$E$13:$E$32)))} -> 0 | AG4: =IF(A4="","",IF(COUNTIF('2) Income'!$D$13:$D$32,"Monthly")=0,0,IF(B4="N",SUMIFS('2) Income'!$E$13:$E$32,'2) Income'!$D$13:$D$32,"monthly",'2) Income'!$F$13:$F$32,"<="&$A4,'2) Income'!$I$13:$I$32,DAY(A4)),SUMIFS('2) Income'!$E$13:$E$32,'2) Income'!$D$13:$D$32,"monthly",'2) Income'!$F$13:$F$32,"<="&$A4,'2) Income'!$I$13:$I$32,">="&DAY(A4))))) -> 0 | AH4: {=IF(A4="","",IF(COUNTIF('2) Income'!$D$13:$D$32,"Yearly")=0,0,SUMPRODUCT(--('2) Income'!$D$13:$D$32="Yearly"),--('2) Income'!$F$13:$F$32<=A4),IF(B4="N",--('2) Income'!$I$13:$I$32=DAY(A4)),--('2) Income'!$I$13:$I$32>=DAY(A4))),--(IFERROR(MOD('2) Income'!$H$13:$H$32-MONTH(A4)+12,12),1)=0),'2) Income'!$E$13:$E$32)))} -> 0 | AI4: =IF(A4="","",IF(COUNTIF('2) Income'!$D$13:$D$32,"one-time")=0,0,SUMIFS('2) Income'!$E$13:$E$32,'2) Income'!$D$13:$D$32,"one-time",'2) Income'!$F$13:$F$32,"="&$A4))) -> 0 | AJ4: =IF(A4="","",SUM(Z4:AI4)) -> 0 | AL4: SUMIFS('2) Income'!$E$13:$E$32,'2) Income'!$D$13:$D$32,"monthly",'2) Income'!$F$13:$F$32,"<="&$A2,'2) Income'!$I$13:$I$32,"Day "&DAY(A2))
A5: =IF(A4="","",IF(A4+1<='1) Period'!$E$21,A4+1,"")) -> 45477 | B5: =IF(DAY(A5)>DAY(A5+1),"Y","N") -> N | C5: =IF(WEEKDAY(A5,2)>5,"Y","F") -> F | D5: =IF(A5="","",IF(TEXT(A5,"dddd")='4) Happy Money'!$E$23,WAllowance,0)) -> 0 | E5: =IF(A5="","",IF(B5="N",SUMIF(TMonthly[Day of the Month],DAY(A5),TMonthly[Amount]),SUMIF(TMonthly[Day of the Month],">="&DAY(A5),TMonthly[Amount]))) -> 35 | F5: {=IF(A5="","",SUMPRODUCT(--(TYearly[Due Date]<=A5),IF(B5="N",--(TYearly[Day]=DAY(A5)),--(TYearly[Day]>=DAY(A5))),--(IFERROR(MOD(TYearly[Month]-MONTH(A5)+12,12),1)=0),TYearly[Amount]))} -> 0 | G5: =IF(A5="","",SUMIF(TOneTime[Due Date],A5,TOneTime[Amount])) -> 0 | H5: {=IF(A5="","",IF(COUNTIF(TOther[Frequency],$H$1)=0,0,SUMPRODUCT(--(IFERROR(MOD(A5-TOther[Start Date],7),1)=0),--(TOther[Frequency]=$H$1),--(TOther[Start Date]<=A5),--(TOther[End Date Calc]>=A5),TOther[Amount])))} -> 0 | I5: {=IF(A5="","",IF(COUNTIF(TOther[Frequency],$I$1)=0,0,SUMPRODUCT(--(IFERROR(MOD(A5-TOther[Start Date],14),1)=0),--(TOther[Frequency]=$I$1),--(TOther[Start Date]<=A5),--(TOther[End Date Calc]>=A5),TOther[Amount])))} -> 0 | J5: =IF(A5="","",IF(COUNTIF(TOther[Frequency],$J$1)=0,0,IF(OR(DAY(A5)=1,DAY(A5)=15),SUMIFS(TOther[Amount],TOther[Frequency],$J$1,TOther[Start Date],"<="&$A5,TOther[End Date Calc],">="&A5),0))) -> 0 | K5: =IF(A5="","",IF(COUNTIF(TOther[Frequency],$K$1)=0,0,IF(A5=(A5-DAY(A5)+1+2*7-WEEKDAY(A5-DAY(A5)+8-4,1)),SUMIFS(TOther[Amount],TOther[Frequency],$K$1,TOther[Start Date],"<="&$A5,TOther[End Date Calc],">="&A5),0))) -> 0 | L5: =IF(A5="","",IF(COUNTIF(TOther[Frequency],$L$1)=0,0,IF(A5=(A5-DAY(A5)+1+3*7-WEEKDAY(A5-DAY(A5)+8-4,1)),SUMIFS(TOther[Amount],TOther[Frequency],$L$1,TOther[Start Date],"<="&$A5,TOther[End Date Calc],">="&A5),0))) -> 0 | M5: =IF(A5="","",IF(COUNTIF(TOther[Frequency],$M$1)=0,0,IF(A5=(A5-DAY(A5)+1+4*7-WEEKDAY(A5-DAY(A5)+8-4,1)),SUMIFS(TOther[Amount],TOther[Frequency],$M$1,TOther[Start Date],"<="&$A5,TOther[End Date Calc],">="&A5),0))) -> 0 | N5: {=IF(A5="","",IF(COUNTIF(TOther[Frequency],$N$1)=0,0,SUMPRODUCT(--(IFERROR(MOD(A5-TOther[Start Date],28),1)=0),--(TOther[Frequency]=$N$1),--(TOther[Start Date]<=A5),--(TOther[End Date Calc]>=A5),TOther[Amount])))} -> 0 | O5: {=IF(A5="","",IF(COUNTIF(TOther[Frequency],$O$1)=0,0,SUMPRODUCT(--(IFERROR(MOD(A5-TOther[Start Date],42),1)=0),--(TOther[Frequency]=$O$1),--(TOther[Start Date]<=A5),--(TOther[End Date Calc]>=A5),TOther[Amount])))} -> 0 | P5: {=IF(A5="","",IF(COUNTIF(TOther[Frequency],$P$1)=0,0,SUMPRODUCT(--(IFERROR(MOD(A5-TOther[Start Date],56),1)=0),--(TOther[Frequency]=$P$1),--(TOther[Start Date]<=A5),--(TOther[End Date Calc]>=A5),TOther[Amount])))} -> 0 | Q5: =IF(A5="","",IF(COUNTIF(TOther[Frequency],$Q$1)=0,0,IF(B5="N",SUMIFS(TOther[Amount],TOther[Frequency],$Q$1,TOther[Start Date],"<="&$A5,TOther[End Date Calc],">="&A5,TOther[Start Day],DAY(A5)),SUMIFS(TOther[Amount],TOther[Frequency],$Q$1,TOther[Start Date],"<="&$A5,TOther[End Date Calc],">="&A5,TOther[Start Day],">="&DAY(A5))))) -> 0 | R5: {=IF(A5="","",IF(COUNTIF(TOther[Frequency],R$1)=0,0,SUMPRODUCT(--(TOther[Frequency]=R$1),--(TOther[Start Date]<=A5),--(TOther[End Date Calc]>=A5),IF(B5="N",--(TOther[Start Day]=DAY(A5)),--(TOther[Start Day]>=DAY(A5))),--(IFERROR(MOD(TOther[Start Month]-MONTH(A5)+2,2),1)=0),TOther[Amount])))} -> 0 | S5: {=IF(A5="","",IF(COUNTIF(TOther[Frequency],S$1)=0,0,SUMPRODUCT(--(TOther[Frequency]=S$1),--(TOther[Start Date]<=A5),--(TOther[End Date Calc]>=A5),IF(B5="N",--(TOther[Start Day]=DAY(A5)),--(TOther[Start Day]>=DAY(A5))),--(IFERROR(MOD(TOther[Start Month]-MONTH(A5)+3,3),1)=0),TOther[Amount])))} -> 0 | T5: {=IF($A5="","",IF(COUNTIF(TOther[Frequency],T$1)=0,0,SUMPRODUCT(--(TOther[Frequency]=T$1),--(TOther[Start Date]<=$A5),--(TOther[End Date Calc]>=$A5),IF($B5="N",--(TOther[Start Day]=DAY($A5)),--(TOther[Start Day]>=DAY($A5))),--(IFERROR(MOD(TOther[Start Month]-MONTH($A5)+4,4),1)=0),TOther[Amount])))} -> 0 | U5: {=IF(A5="","",IF(COUNTIF(TOther[Frequency],$U$1)=0,0,SUMPRODUCT(--(TOther[Frequency]=$U$1),--(TOther[Start Date]<=A5),--(TOther[End Date Calc]>=A5),IF(B5="N",--(TOther[Start Day]=DAY(A5)),--(TOther[Start Day]>=DAY(A5))),--(IFERROR(MOD(TOther[Start Month]-MONTH(A5)+6,6),1)=0),TOther[Amount])))} -> 0 | V5: {=IF(A5="","",IF(COUNTIF(TOther[Frequency],$V$1)=0,0,SUMPRODUCT(--(TOther[Frequency]=$V$1),--(TOther[Start Date]<=A5),--(TOther[End Date Calc]>=A5),IF(B5="N",--(TOther[Start Day]=DAY(A5)),--(TOther[Start Day]>=DAY(A5))),--(IFERROR(MOD(TOther[Start Month]-MONTH(A5)+12,12),1)=0),TOther[Amount])))} -> 0 | W5: =IF(A5="","",SUMIFS(TOther[Amount],TOther[Start Date],A5,TOther[Frequency],$W$1)) -> 0 | X5: =IF(A5="","",SUM(E5:W5)) -> 35 | Y5: =IF(A5="","",SUM(H5:W5)) -> 0 | Z5: {=IF(A5="","",IF(COUNTIF('2) Income'!$D$13:$D$32,"Weekly")=0,0,SUMPRODUCT(--(IFERROR(MOD(A5-'2) Income'!$F$13:$F$32,7),1)=0),--('2) Income'!$D$13:$D$32="Weekly"),--('2) Income'!$F$13:$F$32<=A5),'2) Income'!$E$13:$E$32)))} -> 0 | AA5: {=IF(A5="","",IF(COUNTIF('2) Income'!$D$13:$D$32,"Every Other Week")=0,0,SUMPRODUCT(--(IFERROR(MOD(A5-'2) Income'!$F$13:$F$32,14),1)=0),--('2) Income'!$D$13:$D$32="Every Other Week"),--('2) Income'!$F$13:$F$32<=A5),'2) Income'!$E$13:$E$32)))} -> 0 | AB5: =IF(A5="","",IF(COUNTIF('2) Income'!$D$13:$D$32,"1st and 15th")=0,0,IF(OR(DAY(A5)=1,DAY(A5)=15),SUMIFS('2) Income'!$E$13:$E$32,'2) Income'!$D$13:$D$32,"1st and 15th",'2) Income'!$F$13:$F$32,"<="&$A5),0))) -> 0 | AC5: =IF(A5="","",IF(COUNTIF('2) Income'!$D$13:$D$32,"2nd Wednesday")=0,0,IF(A5=(A5-DAY(A5)+1+2*7-WEEKDAY(A5-DAY(A5)+8-4,1)),SUMIFS('2) Income'!$E$13:$E$32,'2) Income'!$D$13:$D$32,"2nd Wednesday",'2) Income'!$F$13:$F$32,"<="&$A5),0))) -> 0 | AD5: =IF(A5="","",IF(COUNTIF('2) Income'!$D$13:$D$32,"3rd Wednesday")=0,0,IF(A5=(A5-DAY(A5)+1+3*7-WEEKDAY(A5-DAY(A5)+8-4,1)),SUMIFS('2) Income'!$E$13:$E$32,'2) Income'!$D$13:$D$32,"3rd Wednesday",'2) Income'!$F$13:$F$32,"<="&$A5),0))) -> 0 | AE5: =IF(A5="","",IF(COUNTIF('2) Income'!$D$13:$D$32,"4th Wednesday")=0,0,IF(A5=(A5-DAY(A5)+1+4*7-WEEKDAY(A5-DAY(A5)+8-4,1)),SUMIFS('2) Income'!$E$13:$E$32,'2) Income'!$D$13:$D$32,"4th Wednesday",'2) Income'!$F$13:$F$32,"<="&$A5),0))) -> 0 | AF5: {=IF(A5="","",IF(COUNTIF('2) Income'!$D$13:$D$32,"Every 4 Weeks")=0,0,SUMPRODUCT(--(IFERROR(MOD(A5-'2) Income'!$F$13:$F$32,28),1)=0),--('2) Income'!$D$13:$D$32="Every 4 Weeks"),--('2) Income'!$F$13:$F$32<=A5),'2) Income'!$E$13:$E$32)))} -> 0 | AG5: =IF(A5="","",IF(COUNTIF('2) Income'!$D$13:$D$32,"Monthly")=0,0,IF(B5="N",SUMIFS('2) Income'!$E$13:$E$32,'2) Income'!$D$13:$D$32,"monthly",'2) Income'!$F$13:$F$32,"<="&$A5,'2) Income'!$I$13:$I$32,DAY(A5)),SUMIFS('2) Income'!$E$13:$E$32,'2) Income'!$D$13:$D$32,"monthly",'2) Income'!$F$13:$F$32,"<="&$A5,'2) Income'!$I$13:$I$32,">="&DAY(A5))))) -> 0 | AH5: {=IF(A5="","",IF(COUNTIF('2) Income'!$D$13:$D$32,"Yearly")=0,0,SUMPRODUCT(--('2) Income'!$D$13:$D$32="Yearly"),--('2) Income'!$F$13:$F$32<=A5),IF(B5="N",--('2) Income'!$I$13:$I$32=DAY(A5)),--('2) Income'!$I$13:$I$32>=DAY(A5))),--(IFERROR(MOD('2) Income'!$H$13:$H$32-MONTH(A5)+12,12),1)=0),'2) Income'!$E$13:$E$32)))} -> 0 | AI5: =IF(A5="","",IF(COUNTIF('2) Income'!$D$13:$D$32,"one-time")=0,0,SUMIFS('2) Income'!$E$13:$E$32,'2) Income'!$D$13:$D$32,"one-time",'2) Income'!$F$13:$F$32,"="&$A5))) -> 0 | AJ5: =IF(A5="","",SUM(Z5:AI5)) -> 0 | AL5: sum income amount in column E where:
